Workbook

Sheet county_reeds_corrected0310
A1: NAME | B1: STATE_NAME | C1: STATE_FIPS | D1: CNTY_FIPS | E1: FIPS | F1: pFIPS | G1: DEMLAB | H1: PCA_REG
A2: Autauga | B2: Alabama | C2: 01 | D2: 001 | E2: 01001 | F2: p01001 | G2: 267 | H2: 90
A3: Baldwin | B3: Alabama | C3: 01 | D3: 003 | E3: 01003 | F3: p01003 | G3: 267 | H3: 90
A4: Barbour | B4: Alabama | C4: 01 | D4: 005 | E4: 01005 | F4: p01005 | G4: 267 | H4: 90
A5: Bibb | B5: Alabama | C5: 01 | D5: 007 | E5: 01007 | F5: p01007 | G5: 265 | H5: 89
A6: Blount | B6: Alabama | C6: 01 | D6: 009 | E6: 01009 | F6: p01009 | G6: 267 | H6: 90
A7: Bullock | B7: Alabama | C7: 01 | D7: 011 | E7: 01011 | F7: p01011 | G7: 267 | H7: 90
A8: Butler | B8: Alabama | C8: 01 | D8: 013 | E8: 01013 | F8: p01013 | G8: 267 | H8: 90
A9: Calhoun | B9: Alabama | C9: 01 | D9: 015 | E9: 01015 | F9: p01015 | G9: 267 | H9: 90
A10: Chambers | B10: Alabama | C10: 01 | D10: 017 | E10: 01017 | F10: p01017 | G10: 267 | H10: 90
A11: Cherokee | B11: Alabama | C11: 01 | D11: 019 | E11: 01019 | F11: p01019 | G11: 267 | H11: 90
A12: Chilton | B12: Alabama | C12: 01 | D12: 021 | E12: 01021 | F12: p01021 | G12: 267 | H12: 90
A13: Choctaw | B13: Alabama | C13: 01 | D13: 023 | E13: 01023 | F13: p01023 | G13: 265 | H13: 89
... A2385: Sanborn | B2385: South Dakota | C2385: 46 | D2385: 111 | E2385: 46111 | F2385: p46111 | G2385: 110 | H2385: 38
A2386: Oglala Lakota | B2386: South Dakota | C2386: 46 | D2386: 102 | E2386: 46102 | F2386: p46102 | G2386: 107 | H2386: 38
A2387: Spink | B2387: South Dakota | C2387: 46 | D2387: 115 | E2387: 46115 | F2387: p46115 | G2387: 109 | H2387: 38
A2388: Stanley | B2388: South Dakota | C2388: 46 | D2388: 117 | E2388: 46117 | F2388: p46117 | G2388: 106 | H2388: 38
A2389: Sully | B2389: South Dakota | C2389: 46 | D2389: 119 | E2389: 46119 | F2389: p46119 | G2389: 105 | H2389: 38
A2390: Todd | B2390: South Dakota | C2390: 46 | D2390: 121 | E2390: 46121 | F2390: p46121 | G2390: 108 | H2390: 38
A2391: Tripp | B2391: South Dakota | C2391: 46 | D2391: 123 | E2391: 46123 | F2391: p46123 | G2391: 108 | H2391: 38
A2392: Turner | B2392: South Dakota | C2392: 46 | D2392: 125 | E2392: 46125 | F2392: p46125 | G2392: 113 | H2392: 38
A2393: Union | B2393: South Dakota | C2393: 46 | D2393: 127 | E2393: 46127 | F2393: p46127 | G2393: 113 | H2393: 38
A2394: Walworth | B2394: South Dakota | C2394: 46 | D2394: 129 | E2394: 46129 | F2394: p46129 | G2394: 105 | H2394: 38
A2395: Yankton | B2395: South Dakota | C2395: 46 | D2395: 135 | E2395: 46135 | F2395: p46135 | G2395: 111 | H2395: 38
A2396: Ziebach | B2396: South Dakota | C2396: 46 | D2396: 137 | E2396: 46137 | F2396: p46137 | G2396: 105 | H2396: 38
A2397: Anderson | B2397: Tennessee | C2397: 47 | D2397: 001 | E2397: 47001 | F2397: p47001 | G2397: 281 | H2397: 92
A2398: Bedford | B2398: Tennessee | C2398: 47 | D2398: 003 | E2398: 47003 | F2398: p47003 | G2398: 279 | H2398: 92
... A3110: Weston | B3110: Wyoming | C3110: 56 | D3110: 045 | E3110: 56045 | F3110: p56045 | G3110: 73 | H3110: 23

Sheet fromanthony01062012
A1: county | B1: state | C1: stateAbb | D1: id | E1: alternative_id | F1: cnty_fips | G1: reeds_reg | H1: PCA | I1: from anthony 01-06-2012
A2: Autauga | B2: Alabama | C2: =VLOOKUP(B2,StateAbb!$A$3:$C$62,3,FALSE()) -> AL | D2: Autauga-Alabama | E2: =CONCATENATE(C2,A2) -> ALAutauga | F2: 1 | G2: 267 | H2: =IFERROR(VLOOKUP(G2,county_reeds_corrected0310!$G$1:$H$3110,2,FALSE()),0) -> 90
A3: Baldwin | B3: Alabama | C3: =VLOOKUP(B3,StateAbb!$A$3:$C$62,3,FALSE()) -> AL | D3: Baldwin-Alabama | E3: =CONCATENATE(C3,A3) -> ALBaldwin | F3: 3 | G3: 267 | H3: =IFERROR(VLOOKUP(G3,county_reeds_corrected0310!$G$1:$H$3110,2,FALSE()),0) -> 90
A4: Barbour | B4: Alabama | C4: =VLOOKUP(B4,StateAbb!$A$3:$C$62,3,FALSE()) -> AL | D4: Barbour-Alabama | E4: =CONCATENATE(C4,A4) -> ALBarbour | F4: 5 | G4: 267 | H4: =IFERROR(VLOOKUP(G4,county_reeds_corrected0310!$G$1:$H$3110,2,FALSE()),0) -> 90
A5: Bibb | B5: Alabama | C5: =VLOOKUP(B5,StateAbb!$A$3:$C$62,3,FALSE()) -> AL | D5: Bibb-Alabama | E5: =CONCATENATE(C5,A5) -> ALBibb | F5: 7 | G5: 265 | H5: =IFERROR(VLOOKUP(G5,county_reeds_corrected0310!$G$1:$H$3110,2,FALSE()),0) -> 89
A6: Blount | B6: Alabama | C6: =VLOOKUP(B6,StateAbb!$A$3:$C$62,3,FALSE()) -> AL | D6: Blount-Alabama | E6: =CONCATENATE(C6,A6) -> ALBlount | F6: 9 | G6: 267 | H6: =IFERROR(VLOOKUP(G6,county_reeds_corrected0310!$G$1:$H$3110,2,FALSE()),0) -> 90
A7: Bullock | B7: Alabama | C7: =VLOOKUP(B7,StateAbb!$A$3:$C$62,3,FALSE()) -> AL | D7: Bullock-Alabama | E7: =CONCATENATE(C7,A7) -> ALBullock | F7: 11 | G7: 267 | H7: =IFERROR(VLOOKUP(G7,county_reeds_corrected0310!$G$1:$H$3110,2,FALSE()),0) -> 90
A8: Butler | B8: Alabama | C8: =VLOOKUP(B8,StateAbb!$A$3:$C$62,3,FALSE()) -> AL | D8: Butler-Alabama | E8: =CONCATENATE(C8,A8) -> ALButler | F8: 13 | G8: 267 | H8: =IFERROR(VLOOKUP(G8,county_reeds_corrected0310!$G$1:$H$3110,2,FALSE()),0) -> 90
A9: Calhoun | B9: Alabama | C9: =VLOOKUP(B9,StateAbb!$A$3:$C$62,3,FALSE()) -> AL | D9: Calhoun-Alabama | E9: =CONCATENATE(C9,A9) -> ALCalhoun | F9: 15 | G9: 267 | H9: =IFERROR(VLOOKUP(G9,county_reeds_corrected0310!$G$1:$H$3110,2,FALSE()),0) -> 90
A10: Chambers | B10: Alabama | C10: =VLOOKUP(B10,StateAbb!$A$3:$C$62,3,FALSE()) -> AL | D10: Chambers-Alabama | E10: =CONCATENATE(C10,A10) -> ALChambers | F10: 17 | G10: 267 | H10: =IFERROR(VLOOKUP(G10,county_reeds_corrected0310!$G$1:$H$3110,2,FALSE()),0) -> 90
A11: Cherokee | B11: Alabama | C11: =VLOOKUP(B11,StateAbb!$A$3:$C$62,3,FALSE()) -> AL | D11: Cherokee-Alabama | E11: =CONCATENATE(C11,A11) -> ALCherokee | F11: 19 | G11: 267 | H11: =IFERROR(VLOOKUP(G11,county_reeds_corrected0310!$G$1:$H$3110,2,FALSE()),0) -> 90
A12: Chilton | B12: Alabama | C12: =VLOOKUP(B12,StateAbb!$A$3:$C$62,3,FALSE()) -> AL | D12: Chilton-Alabama | E12: =CONCATENATE(C12,A12) -> ALChilton | F12: 21 | G12: 267 | H12: =IFERROR(VLOOKUP(G12,county_reeds_corrected0310!$G$1:$H$3110,2,FALSE()),0) -> 90
A13: Choctaw | B13: Alabama | C13: =VLOOKUP(B13,StateAbb!$A$3:$C$62,3,FALSE()) -> AL | D13: Choctaw-Alabama | E13: =CONCATENATE(C13,A13) -> ALChoctaw | F13: 23 | G13: 265 | H13: =IFERROR(VLOOKUP(G13,county_reeds_corrected0310!$G$1:$H$3110,2,FALSE()),0) -> 89
... A68: Winston | B68: Alabama | C68: =VLOOKUP(B68,StateAbb!$A$3:$C$62,3,FALSE()) -> AL | D68: Winston-Alabama | E68: =CONCATENATE(C68,A68) -> ALWinston | F68: 133 | G68: 265 | H68: =IFERROR(VLOOKUP(G68,county_reeds_corrected0310!$G$1:$H$3110,2,FALSE()),0) -> 89
A69: Aleutians East | B69: Alaska | C69: =VLOOKUP(B69,StateAbb!$A$3:$C$62,3,FALSE()) -> AK | D69: Aleutians East-Alaska | E69: =CONCATENATE(C69,A69) -> AKAleutians East | F69: 13 | H69: =IFERROR(VLOOKUP(G69,county_reeds_corrected0310!$G$1:$H$3110,2,FALSE()),0) -> 0
A70: Aleutians West | B70: Alaska | C70: =VLOOKUP(B70,StateAbb!$A$3:$C$62,3,FALSE()) -> AK | D70: Aleutians West-Alaska | E70: =CONCATENATE(C70,A70) -> AKAleutians West | F70: 16 | H70: =IFERROR(VLOOKUP(G70,county_reeds_corrected0310!$G$1:$H$3110,2,FALSE()),0) -> 0
A71: Anchorage | B71: Alaska | C71: =VLOOKUP(B71,StateAbb!$A$3:$C$62,3,FALSE()) -> AK | D71: Anchorage-Alaska | E71: =CONCATENATE(C71,A71) -> AKAnchorage | F71: 20 | H71: =IFERROR(VLOOKUP(G71,county_reeds_corrected0310!$G$1:$H$3110,2,FALSE()),0) -> 0
A72: Bethel | B72: Alaska | C72: =VLOOKUP(B72,StateAbb!$A$3:$C$62,3,FALSE()) -> AK | D72: Bethel-Alaska | E72: =CONCATENATE(C72,A72) -> AKBethel | F72: 50 | H72: =IFERROR(VLOOKUP(G72,county_reeds_corrected0310!$G$1:$H$3110,2,FALSE()),0) -> 0
A73: Bristol Bay | B73: Alaska | C73: =VLOOKUP(B73,StateAbb!$A$3:$C$62,3,FALSE()) -> AK | D73: Bristol Bay-Alaska | E73: =CONCATENATE(C73,A73) -> AKBristol Bay | F73: 60 | H73: =IFERROR(VLOOKUP(G73,county_reeds_corrected0310!$G$1:$H$3110,2,FALSE()),0) -> 0
A74: Denali | B74: Alaska | C74: =VLOOKUP(B74,StateAbb!$A$3:$C$62,3,FALSE()) -> AK | D74: Denali-Alaska | E74: =CONCATENATE(C74,A74) -> AKDenali | F74: 68 | H74: =IFERROR(VLOOKUP(G74,county_reeds_corrected0310!$G$1:$H$3110,2,FALSE()),0) -> 0
A75: Dillingham | B75: Alaska | C75: =VLOOKUP(B75,StateAbb!$A$3:$C$62,3,FALSE()) -> AK | D75: Dillingham-Alaska | E75: =CONCATENATE(C75,A75) -> AKDillingham | F75: 70 | H75: =IFERROR(VLOOKUP(G75,county_reeds_corrected0310!$G$1:$H$3110,2,FALSE()),0) -> 0
A76: Fairbanks North Star | B76: Alaska | C76: =VLOOKUP(B76,StateAbb!$A$3:$C$62,3,FALSE()) -> AK | D76: Fairbanks North Star-Alaska | E76: =CONCATENATE(C76,A76) -> AKFairbanks North Star | F76: 90 | H76: =IFERROR(VLOOKUP(G76,county_reeds_corrected0310!$G$1:$H$3110,2,FALSE()),0) -> 0
A77: Haines | B77: Alaska | C77: =VLOOKUP(B77,StateAbb!$A$3:$C$62,3,FALSE()) -> AK | D77: Haines-Alaska | E77: =CONCATENATE(C77,A77) -> AKHaines | F77: 100 | H77: =IFERROR(VLOOKUP(G77,county_reeds_corrected0310!$G$1:$H$3110,2,FALSE()),0) -> 0
A78: Juneau | B78: Alaska | C78: =VLOOKUP(B78,StateAbb!$A$3:$C$62,3,FALSE()) -> AK | D78: Juneau-Alaska | E78: =CONCATENATE(C78,A78) -> AKJuneau | F78: 110 | H78: =IFERROR(VLOOKUP(G78,county_reeds_corrected0310!$G$1:$H$3110,2,FALSE()),0) -> 0
A79: Kenai Peninsula | B79: Alaska | C79: =VLOOKUP(B79,StateAbb!$A$3:$C$62,3,FALSE()) -> AK | D79: Kenai Peninsula-Alaska | E79: =CONCATENATE(C79,A79) -> AKKenai Peninsula | F79: 122 | H79: =IFERROR(VLOOKUP(G79,county_reeds_corrected0310!$G$1:$H$3110,2,FALSE()),0) -> 0
A80: Ketchikan Gateway | B80: Alaska | C80: =VLOOKUP(B80,StateAbb!$A$3:$C$62,3,FALSE()) -> AK | D80: Ketchikan Gateway-Alaska | E80: =CONCATENATE(C80,A80) -> AKKetchikan Gateway | F80: 130 | H80: =IFERROR(VLOOKUP(G80,county_reeds_corrected0310!$G$1:$H$3110,2,FALSE()),0) -> 0
... A95: Yukon-Koyukuk | B95: Alaska | C95: =VLOOKUP(B95,StateAbb!$A$3:$C$62,3,FALSE()) -> AK | D95: Yukon-Koyukuk-Alaska | E95: =CONCATENATE(C95,A95) -> AKYukon-Koyukuk | F95: 290 | H95: =IFERROR(VLOOKUP(G95,county_reeds_corrected0310!$G$1:$H$3110,2,FALSE()),0) -> 0
A96: Apache | B96: Arizona | C96: =VLOOKUP(B96,StateAbb!$A$3:$C$62,3,FALSE()) -> AZ | D96: Apache-Arizona | E96: =CONCATENATE(C96,A96) -> AZApache | F96: 1 | G96: 55 | H96: =IFERROR(VLOOKUP(G96,county_reeds_corrected0310!$G$1:$H$3110,2,FALSE()),0) -> 29
A97: Cochise | B97: Arizona | C97: =VLOOKUP(B97,StateAbb!$A$3:$C$62,3,FALSE()) -> AZ | D97: Cochise-Arizona | E97: =CONCATENATE(C97,A97) -> AZCochise | F97: 3 | G97: 59 | H97: =IFERROR(VLOOKUP(G97,county_reeds_corrected0310!$G$1:$H$3110,2,FALSE()),0) -> 28
A98: Coconino | B98: Arizona | C98: =VLOOKUP(B98,StateAbb!$A$3:$C$62,3,FALSE()) -> AZ | D98: Coconino-Arizona | E98: =CONCATENATE(C98,A98) -> AZCoconino | F98: 5 | G98: 54 | H98: =IFERROR(VLOOKUP(G98,county_reeds_corrected0310!$G$1:$H$3110,2,FALSE()),0) -> 28
A99: Gila | B99: Arizona | C99: =VLOOKUP(B99,StateAbb!$A$3:$C$62,3,FALSE()) -> AZ | D99: Gila-Arizona | E99: =CONCATENATE(C99,A99) -> AZGila | F99: 7 | G99: 59 | H99: =IFERROR(VLOOKUP(G99,county_reeds_corrected0310!$G$1:$H$3110,2,FALSE()),0) -> 28
A100: Graham | B100: Arizona | C100: =VLOOKUP(B100,StateAbb!$A$3:$C$62,3,FALSE()) -> AZ | D100: Graham-Arizona | E100: =CONCATENATE(C100,A100) -> AZGraham | F100: 9 | G100: 59 | H100: =IFERROR(VLOOKUP(G100,county_reeds_corrected0310!$G$1:$H$3110,2,FALSE()),0) -> 28
A101: Greenlee | B101: Arizona | C101: =VLOOKUP(B101,StateAbb!$A$3:$C$62,3,FALSE()) -> AZ | D101: Greenlee-Arizona | E101: =CONCATENATE(C101,A101) -> AZGreenlee | F101: 11 | G101: 59 | H101: =IFERROR(VLOOKUP(G101,county_reeds_corrected0310!$G$1:$H$3110,2,FALSE()),0) -> 28
A102: La Paz | B102: Arizona | C102: =VLOOKUP(B102,StateAbb!$A$3:$C$62,3,FALSE()) -> AZ | D102: La Paz-Arizona | E102: =CONCATENATE(C102,A102) -> AZLa Paz | F102: 12 | G102: 56 | H102: =IFERROR(VLOOKUP(G102,county_reeds_corrected0310!$G$1:$H$3110,2,FALSE()),0) -> 28
A103: Maricopa | B103: Arizona | C103: =VLOOKUP(B103,StateAbb!$A$3:$C$62,3,FALSE()) -> AZ | D103: Maricopa-Arizona | E103: =CONCATENATE(C103,A103) -> AZMaricopa | F103: 13 | G103: 57 | H103: =IFERROR(VLOOKUP(G103,county_reeds_corrected0310!$G$1:$H$3110,2,FALSE()),0) -> 28
A104: Mohave | B104: Arizona | C104: =VLOOKUP(B104,StateAbb!$A$3:$C$62,3,FALSE()) -> AZ | D104: Mohave-Arizona | E104: =CONCATENATE(C104,A104) -> AZMohave | F104: 15 | G104: 53 | H104: =IFERROR(VLOOKUP(G104,county_reeds_corrected0310!$G$1:$H$3110,2,FALSE()),0) -> 27
A105: Navajo | B105: Arizona | C105: =VLOOKUP(B105,StateAbb!$A$3:$C$62,3,FALSE()) -> AZ | D105: Navajo-Arizona | E105: =CONCATENATE(C105,A105) -> AZNavajo | F105: 17 | G105: 54 | H105: =IFERROR(VLOOKUP(G105,county_reeds_corrected0310!$G$1:$H$3110,2,FALSE()),0) -> 28
A106: Pima | B106: Arizona | C106: =VLOOKUP(B106,StateAbb!$A$3:$C$62,3,FALSE()) -> AZ | D106: Pima-Arizona | E106: =CONCATENATE(C106,A106) -> AZPima | F106: 19 | G106: 58 | H106: =IFERROR(VLOOKUP(G106,county_reeds_corrected0310!$G$1:$H$3110,2,FALSE()),0) -> 30
A107: Pinal | B107: Arizona | C107: =VLOOKUP(B107,StateAbb!$A$3:$C$62,3,FALSE()) -> AZ | D107: Pinal-Arizona | E107: =CONCATENATE(C107,A107) -> AZPinal | F107: 21 | G107: 57 | H107: =IFERROR(VLOOKUP(G107,county_reeds_corrected0310!$G$1:$H$3110,2,FALSE()),0) -> 28
... A545: Worth | B545: Georgia | C545: =VLOOKUP(B545,StateAbb!$A$3:$C$62,3,FALSE()) -> GA | D545: Worth-Georgia | E545: =CONCATENATE(C545,A545) -> GAWorth | F545: 321 | G545: 275 | H545: =IFERROR(VLOOKUP(G545,county_reeds_corrected0310!$G$1:$H$3110,2,FALSE()),0) -> 94
...

Sheet StateAbb
A1: State | B1: Standard | C1: Postal | D1: Capital City
B2: Abbreviation | C2: Abbreviation
A3: Alabama | B3: Ala. | C3: AL | D3: Montgomery
A4: Alaska | B4: Alaska | C4: AK | D4: Juneau
A5: Arizona | B5: Ariz. | C5: AZ | D5: Phoenix
A6: Arkansas | B6: Ark. | C6: AR | D6: Little Rock
A7: California | B7: Calif. | C7: CA | D7: Sacramento
A8: Colorado | B8: Colo. | C8: CO | D8: Denver
A9: Connecticut | B9: Conn. | C9: CT | D9: Hartford
A10: Delaware | B10: Del. | C10: DE | D10: Dover
A11: Florida | B11: Fla. | C11: FL | D11: Tallahassee
A12: Georgia | B12: Ga. | C12: GA | D12: Atlanta
A13: Hawaii | B13: Hawaii | C13: HI | D13: Honolulu
A14: Idaho | B14: Idaho | C14: ID | D14: Boise
... A61: Virgin Islands | B61: V.I. | C61: VI | D61: Charlotte Amalie

Sheet Sheet1
A1: DOE/EIA ORIS plant or facility code | B1: Plant state abbreviation | D1: Plant name
A2: ORISPL | B2: PSTATABB | C2: COUNTY | D2: PNAME | E2: alternative-ID | F2: PCA | G2: ResourceRegion
A3: 57053 | B3: AK | C3: Wade Hampton | D3: Alakanuk | E3: AKWade Hampton | F3: 0 | G3: 0
A4: 57053 | B4: AK | C4: Wade Hampton | D4: Alakanuk | E4: AKWade Hampton | F4: 0 | G4: 0
A5: 57053 | B5: AK | C5: Wade Hampton | D5: Alakanuk | E5: AKWade Hampton | F5: 0 | G5: 0
A6: 75 | B6: AK | C6: Anchorage | D6: Anchorage 1 | E6: AKAnchorage | F6: 0 | G6: 0
A7: 75 | B7: AK | C7: Anchorage | D7: Anchorage 1 | E7: AKAnchorage | F7: 0 | G7: 0
A8: 75 | B8: AK | C8: Anchorage | D8: Anchorage 1 | E8: AKAnchorage | F8: 0 | G8: 0
A9: 75 | B9: AK | C9: Anchorage | D9: Anchorage 1 | E9: AKAnchorage | F9: 0 | G9: 0
A10: 75 | B10: AK | C10: Anchorage | D10: Anchorage 1 | E10: AKAnchorage | F10: 0 | G10: 0
A11: 75 | B11: AK | C11: Anchorage | D11: Anchorage 1 | E11: AKAnchorage | F11: 0 | G11: 0
A12: 7462 | B12: AK | C12: Juneau | D12: Angoon | E12: AKJuneau | F12: 0 | G12: 0
A13: 7462 | B13: AK | C13: Juneau | D13: Angoon | E13: AKJuneau | F13: 0 | G13: 0
A14: 7462 | B14: AK | C14: Juneau | D14: Angoon | E14: AKJuneau | F14: 0 | G14: 0
... A21: 7250 | B21: AK | C21: Juneau | D21: Auke Bay | E21: AKJuneau | F21: 0 | G21: 0
A22: 79 | B22: AK | C22: Fairbanks | D22: Aurora Energy LLC Chena | E22: AKFairbanks | F22: =#N/A -> #N/A | G22: =#N/A -> #N/A
A23: 79 | B23: AK | C23: Fairbanks | D23: Aurora Energy LLC Chena | E23: AKFairbanks | F23: =#N/A -> #N/A | G23: =#N/A -> #N/A
A24: 79 | B24: AK | C24: Fairbanks | D24: Aurora Energy LLC Chena | E24: AKFairbanks | F24: =#N/A -> #N/A | G24: =#N/A -> #N/A
A25: 79 | B25: AK | C25: Fairbanks | D25: Aurora Energy LLC Chena | E25: AKFairbanks | F25: =#N/A -> #N/A | G25: =#N/A -> #N/A
A26: 7173 | B26: AK | C26: North Slope | D26: Barrow | E26: AKNorth Slope | F26: 0 | G26: 0
A27: 7173 | B27: AK | C27: North Slope | D27: Barrow | E27: AKNorth Slope | F27: 0 | G27: 0
A28: 7173 | B28: AK | C28: North Slope | D28: Barrow | E28: AKNorth Slope | F28: 0 | G28: 0
A29: 7173 | B29: AK | C29: North Slope | D29: Barrow | E29: AKNorth Slope | F29: 0 | G29: 0
A30: 7173 | B30: AK | C30: North Slope | D30: Barrow | E30: AKNorth Slope | F30: 0 | G30: 0
A31: 7173 | B31: AK | C31: North Slope | D31: Barrow | E31: AKNorth Slope | F31: 0 | G31: 0
A32: 7173 | B32: AK | C32: North Slope | D32: Barrow | E32: AKNorth Slope | F32: 0 | G32: 0
A33: 6580 | B33: AK | C33: Ketchikan | D33: Beaver Falls | E33: AKKetchikan | F33: =#N/A -> #N/A | G33: =#N/A -> #N/A
A34: 6580 | B34: AK | C34: Ketchikan | D34: Beaver Falls | E34: AKKetchikan | F34: =#N/A -> #N/A | G34: =#N/A -> #N/A
A35: 6580 | B35: AK | C35: Ketchikan | D35: Beaver Falls | E35: AKKetchikan | F35: =#N/A -> #N/A | G35: =#N/A -> #N/A
A36: 96 | B36: AK | C36: Kenai Peninsula | D36: Beluga | E36: AKKenai Peninsula | F36: 0 | G36: 0
A37: 96 | B37: AK | C37: Kenai Peninsula | D37: Beluga | E37: AKKenai Peninsula | F37: 0 | G37: 0
A38: 96 | B38: AK | C38: Kenai Peninsula | D38: Beluga | E38: AKKenai Peninsula | F38: 0 | G38: 0
A39: 96 | B39: AK | C39: Kenai Peninsula | D39: Beluga | E39: AKKenai Peninsula | F39: 0 | G39: 0
A40: 96 | B40: AK | C40: Kenai Peninsula | D40: Beluga | E40: AKKenai Peninsula | F40: 0 | G40: 0
A41: 96 | B41: AK | C41: Kenai Peninsula | D41: Beluga | E41: AKKenai Peninsula | F41: 0 | G41: 0
A42: 96 | B42: AK | C42: Kenai Peninsula | D42: Beluga | E42: AKKenai Peninsula | F42: 0 | G42: 0
A43: 6292 | B43: AK | C43: Kenai Peninsula | D43: Bernice Lake | E43: AKKenai Peninsula | F43: 0 | G43: 0
A44: 6292 | B44: AK | C44: Kenai Peninsula | D44: Bernice Lake | E44: AKKenai Peninsula | F44: 0 | G44: 0
A45: 6292 | B45: AK | C45: Kenai Peninsula | D45: Bernice Lake | E45: AKKenai Peninsula | F45: 0 | G45: 0
A46: 6566 | B46: AK | C46: Bethel | D46: Bethel | E46: AKBethel | F46: 0 | G46: 0
...
